Workbook
Name Slicer_buy_date__Month: #N/A
Name Slicer_buy_date__Year: #N/A
Name Slicer_campaign_name: #N/A

Sheet Kohort analizi
B1: Müştəri sayı | C1: Column Labels
C2: 2022 | O2: 2023
B3: Row Labels | C3: yan | D3: fev | E3: mar | F3: apr | G3: may | H3: iyn | I3: iyl | J3: avq | K3: sen | L3: okt | M3: noy | N3: dek | O3: yan | P3: fev | Q3: mar | R3: apr
B4: 0 | C4: 117 | D4: 85 | E4: 85 | F4: 94 | G4: 100 | H4: 119 | I4: 113 | J4: 143 | K4: 122 | L4: 137 | M4: 125 | N4: 132 | O4: 136 | P4: 112 | Q4: 130 | R4: 134
B5: 1 | C5: 56 | D5: 58 | E5: 49 | F5: 69 | G5: 53 | H5: 86 | I5: 73 | J5: 103 | K5: 96 | L5: 108 | M5: 105 | N5: 106 | O5: 119 | P5: 109 | Q5: 128 | R5: 133
B6: 2 | C6: 86 | D6: 58 | E6: 64 | F6: 72 | G6: 88 | H6: 93 | I6: 87 | J6: 130 | K6: 101 | L6: 132 | M6: 115 | N6: 124 | O6: 135 | P6: 110 | Q6: 130
B7: 3 | C7: 76 | D7: 58 | E7: 62 | F7: 78 | G7: 83 | H7: 90 | I7: 93 | J7: 124 | K7: 107 | L7: 120 | M7: 117 | N7: 128 | O7: 133 | P7: 112
B8: 4 | C8: 76 | D8: 62 | E8: 73 | F8: 69 | G8: 70 | H8: 105 | I8: 91 | J8: 125 | K8: 110 | L8: 125 | M8: 117 | N8: 129 | O8: 134
B9: 5 | C9: 77 | D9: 65 | E9: 56 | F9: 73 | G9: 78 | H9: 103 | I9: 100 | J9: 124 | K9: 108 | L9: 132 | M9: 115 | N9: 126
B10: 6 | C10: 79 | D10: 54 | E10: 61 | F10: 78 | G10: 81 | H10: 90 | I10: 90 | J10: 116 | K10: 113 | L10: 129 | M10: 113
B11: 7 | C11: 84 | D11: 64 | E11: 67 | F11: 75 | G11: 79 | H11: 97 | I11: 86 | J11: 125 | K11: 104 | L11: 126
B12: 8 | C12: 74 | D12: 64 | E12: 63 | F12: 68 | G12: 83 | H12: 93 | I12: 99 | J12: 118 | K12: 110
B13: 9 | C13: 80 | D13: 60 | E13: 63 | F13: 71 | G13: 80 | H13: 101 | I13: 91 | J13: 130
B14: 10 | C14: 83 | D14: 66 | E14: 55 | F14: 77 | G14: 86 | H14: 91 | I14: 96
B15: 11 | C15: 87 | D15: 61 | E15: 68 | F15: 80 | G15: 80 | H15: 98
B16: 12 | C16: 78 | D16: 62 | E16: 70 | F16: 68 | G16: 82
B17: 13 | C17: 75 | D17: 62 | E17: 60 | F17: 75
B18: 14 | C18: 86 | D18: 59 | E18: 57
B19: 15 | C19: 84 | D19: 69
B20: 16 | C20: 77
B24: Geri dönən müştəri faizi | C24: Column Labels
C25: 2022 | O25: 2023
B26: Row Labels | C26: yan | D26: fev | E26: mar | F26: apr | G26: may | H26: iyn | I26: iyl | J26: avq | K26: sen | L26: okt | M26: noy | N26: dek | O26: yan | P26: fev | Q26: mar | R26: apr
B27: 0 | C27: 1 | D27: 1 | E27: 1 | F27: 1 | G27: 1 | H27: 1 | I27: 1 | J27: 1 | K27: 1 | L27: 1 | M27: 1 | N27: 1 | O27: 1 | P27: 1 | Q27: 1 | R27: 1
B28: 1 | C28: 0.47863248 | D28: 0.68235294 | E28: 0.57647059 | F28: 0.73404255 | G28: 0.53 | H28: 0.72268908 | I28: 0.6460177 | J28: 0.72027972 | K28: 0.78688525 | L28: 0.78832117 | M28: 0.84 | N28: 0.8030303 | O28: 0.875 | P28: 0.97321429 | Q28: 0.98461538 | R28: 0.99253731
B29: 2 | C29: 0.73504274 | D29: 0.68235294 | E29: 0.75294118 | F29: 0.76595745 | G29: 0.88 | H29: 0.78151261 | I29: 0.7699115 | J29: 0.90909091 | K29: 0.82786885 | L29: 0.96350365 | M29: 0.92 | N29: 0.93939394 | O29: 0.99264706 | P29: 0.98214286 | Q29: 1
B30: 3 | C30: 0.64957265 | D30: 0.68235294 | E30: 0.72941176 | F30: 0.82978723 | G30: 0.83 | H30: 0.75630252 | I30: 0.82300885 | J30: 0.86713287 | K30: 0.87704918 | L30: 0.87591241 | M30: 0.936 | N30: 0.96969697 | O30: 0.97794118 | P30: 1
B31: 4 | C31: 0.64957265 | D31: 0.72941176 | E31: 0.85882353 | F31: 0.73404255 | G31: 0.7 | H31: 0.88235294 | I31: 0.80530973 | J31: 0.87412587 | K31: 0.90163934 | L31: 0.91240876 | M31: 0.936 | N31: 0.97727273 | O31: 0.98529412
B32: 5 | C32: 0.65811966 | D32: 0.76470588 | E32: 0.65882353 | F32: 0.77659574 | G32: 0.78 | H32: 0.86554622 | I32: 0.88495575 | J32: 0.86713287 | K32: 0.8852459 | L32: 0.96350365 | M32: 0.92 | N32: 0.95454545
B33: 6 | C33: 0.67521368 | D33: 0.63529412 | E33: 0.71764706 | F33: 0.82978723 | G33: 0.81 | H33: 0.75630252 | I33: 0.79646018 | J33: 0.81118881 | K33: 0.92622951 | L33: 0.94160584 | M33: 0.904
B34: 7 | C34: 0.71794872 | D34: 0.75294118 | E34: 0.78823529 | F34: 0.79787234 | G34: 0.79 | H34: 0.81512605 | I34: 0.76106195 | J34: 0.87412587 | K34: 0.85245902 | L34: 0.91970803
B35: 8 | C35: 0.63247863 | D35: 0.75294118 | E35: 0.74117647 | F35: 0.72340426 | G35: 0.83 | H35: 0.78151261 | I35: 0.87610619 | J35: 0.82517483 | K35: 0.90163934
B36: 9 | C36: 0.68376068 | D36: 0.70588235 | E36: 0.74117647 | F36: 0.75531915 | G36: 0.8 | H36: 0.8487395 | I36: 0.80530973 | J36: 0.90909091
B37: 10 | C37: 0.70940171 | D37: 0.77647059 | E37: 0.64705882 | F37: 0.81914894 | G37: 0.86 | H37: 0.76470588 | I37: 0.84955752
B38: 11 | C38: 0.74358974 | D38: 0.71764706 | E38: 0.8 | F38: 0.85106383 | G38: 0.8 | H38: 0.82352941
B39: 12 | C39: 0.66666667 | D39: 0.72941176 | E39: 0.82352941 | F39: 0.72340426 | G39: 0.82
B40: 13 | C40: 0.64102564 | D40: 0.72941176 | E40: 0.70588235 | F40: 0.79787234
B41: 14 | C41: 0.73504274 | D41: 0.69411765 | E41: 0.67058824
B42: 15 | C42: 0.71794872 | D42: 0.81176471
B43: 16 | C43: 0.65811966
...

Sheet Stabillik analizi (TOP3)
A1: Gəlir | B1: İllər-Aylar
A2: Kompaniyalar | B2: BuysViaMailOrder | C2: ChildrenInHH | D2: HandsetRefurbished | E2: HandsetWebCapable | F2: HasCreditCard | G2: Homeownership | H2: MadeCallToRetentionTeam | I2: MaritalStatus | J2: NewCellphoneUser | K2: NonUSTravel | L2: NotNewCellphoneUser | M2: OptOutMailings | N2: OwnsComputer | O2: OwnsMotorcycle | P2: RespondsToMailOffers | Q2: RVOwner | R2: TruckOwner
A3: 2022
A4: yan | B4: 200 | D4: 286 | E4: 372 | F4: 845 | G4: 104 | H4: 128 | J4: 200 | K4: 660 | L4: 308 | M4: 525 | N4: 434 | O4: 140 | Q4: 198 | R4: 52
A5: fev | B5: 225 | D5: 260 | E5: 558 | F5: 845 | G5: 130 | H5: 192 | J5: 200 | K5: 792 | L5: 308 | M5: 750 | N5: 620 | O5: 140 | Q5: 286 | R5: 156
A6: mar | B6: 450 | D6: 442 | E6: 868 | F6: 1170 | G6: 169 | H6: 208 | J6: 450 | K6: 1584 | L6: 588 | M6: 1125 | N6: 1178 | O6: 210 | Q6: 396 | R6: 260
A7: apr | B7: 450 | D7: 468 | E7: 992 | F7: 1430 | G7: 208 | H7: 384 | J7: 625 | K7: 1452 | L7: 560 | M7: 1500 | N7: 1240 | O7: 294 | Q7: 572 | R7: 364
A8: may | B8: 575 | C8: 50 | D8: 702 | E8: 1054 | F8: 1820 | G8: 325 | H8: 432 | J8: 800 | K8: 1914 | L8: 812 | M8: 1875 | N8: 1674 | O8: 378 | Q8: 726 | R8: 520
A9: iyn | B9: 625 | C9: 130 | D9: 728 | E9: 1736 | F9: 2340 | G9: 390 | H9: 608 | J9: 875 | K9: 2112 | L9: 840 | M9: 2400 | N9: 1798 | O9: 364 | P9: 81 | Q9: 880 | R9: 728
A10: iyl | B10: 800 | C10: 200 | D10: 858 | E10: 1922 | F10: 2860 | G10: 520 | H10: 784 | I10: 377 | J10: 1075 | K10: 2706 | L10: 1148 | M10: 2700 | N10: 2232 | O10: 574 | P10: 189 | Q10: 1122 | R10: 858
A11: avq | B11: 975 | C11: 250 | D11: 1118 | E11: 2170 | F11: 2730 | G11: 611 | H11: 752 | I11: 609 | J11: 1225 | K11: 2970 | L11: 1260 | M11: 3300 | N11: 2790 | O11: 560 | P11: 540 | Q11: 1012 | R11: 1066
A12: sen | B12: 1075 | C12: 260 | D12: 1326 | E12: 2666 | F12: 3185 | G12: 624 | H12: 896 | I12: 812 | J12: 1175 | K12: 3168 | L12: 1400 | M12: 3225 | N12: 3162 | O12: 770 | P12: 810 | Q12: 1188 | R12: 988
A13: okt | B13: 1200 | C13: 420 | D13: 1378 | E13: 3782 | F13: 3575 | G13: 754 | H13: 1056 | I13: 1247 | J13: 1575 | K13: 4620 | L13: 1624 | M13: 4275 | N13: 3720 | O13: 840 | P13: 1107 | Q13: 1452 | R13: 1274
A14: noy | B14: 1225 | C14: 440 | D14: 1456 | E14: 4092 | F14: 4225 | G14: 858 | H14: 1184 | I14: 1566 | J14: 1575 | K14: 4686 | L14: 1764 | M14: 4200 | N14: 4526 | O14: 896 | P14: 1296 | Q14: 1606 | R14: 1430
A15: dek | B15: 1450 | C15: 520 | D15: 1742 | E15: 4898 | F15: 4745 | G15: 975 | H15: 1168 | I15: 1914 | J15: 1825 | K15: 5148 | L15: 2184 | M15: 4875 | N15: 4650 | O15: 952 | P15: 1539 | Q15: 1848 | R15: 1716
A16: 2023
A17: yan | B17: 1700 | C17: 680 | D17: 1742 | E17: 5022 | F17: 4745 | G17: 1027 | H17: 1280 | I17: 2146 | J17: 2100 | K17: 5676 | L17: 2324 | M17: 5250 | N17: 5022 | O17: 924 | P17: 1836 | Q17: 1848 | R17: 1690
A18: fev | B18: 1700 | C18: 790 | D18: 1820 | E18: 5518 | F18: 5135 | G18: 1027 | H18: 1264 | I18: 2523 | J18: 2300 | K18: 6534 | L18: 2548 | M18: 5775 | N18: 5084 | O18: 1106 | P18: 2295 | Q18: 2046 | R18: 1846
A19: mar | B19: 1975 | C19: 870 | D19: 2184 | E19: 6200 | F19: 5655 | G19: 1248 | H19: 1600 | I19: 2900 | J19: 2450 | K19: 7128 | L19: 3024 | M19: 6525 | N19: 5952 | O19: 1232 | P19: 2808 | Q19: 2288 | R19: 2366
A20: apr | B20: 2050 | C20: 1050 | D20: 2184 | E20: 6944 | F20: 6240 | G20: 1196 | H20: 1600 | I20: 3103 | J20: 2375 | K20: 7128 | L20: 3024 | M20: 6450 | N20: 6200 | O20: 1274 | P20: 2997 | Q20: 2398 | R20: 2444
A21: may | B21: 2250 | C21: 1040 | D21: 2158 | E21: 6944 | F21: 6435 | G21: 1235 | H21: 1616 | I21: 3306 | J21: 2525 | K21: 6732 | L21: 3192 | M21: 6075 | N21: 6324 | O21: 1274 | P21: 3132 | Q21: 2486 | R21: 2496
A23: Stabillik | B23: =_xlfn.STDEV.S(B4:B21)/AVERAGE(B4:B21) -> 0.58921016 | C23: =_xlfn.STDEV.S(C4:C21)/AVERAGE(C4:C21) -> 0.66376056 | D23: =_xlfn.STDEV.S(D4:D21)/AVERAGE(D4:D21) -> 0.55260985 | E23: =_xlfn.STDEV.S(E4:E21)/AVERAGE(E4:E21) -> 0.70157647 | F23: =_xlfn.STDEV.S(F4:F21)/AVERAGE(F4:F21) -> 0.54861406 | G23: =_xlfn.STDEV.S(G4:G21)/AVERAGE(G4:G21) -> 0.60364397 | H23: =_xlfn.STDEV.S(H4:H21)/AVERAGE(H4:H21) -> 0.56982575 | I23: =_xlfn.STDEV.S(I4:I21)/AVERAGE(I4:I21) -> 0.55149347 | ... R23: =_xlfn.STDEV.S(R4:R21)/AVERAGE(R4:R21) -> 0.677442

Sheet Pareto Analizi
A2: Kompaniyalar | B2: Toplam Gəlir | C2: Kumlyativ faiz Gəlirlər üzrə
A3: NonUSTravel | B3: 65010 | C3: 0.12669699
A4: OptOutMailings | B4: 60825 | C4: 0.2452379
A5: HasCreditCard | B5: 57980 | C5: 0.35823423
A6: OwnsComputer | B6: 56606 | C6: 0.4685528
A7: HandsetWebCapable | B7: 55738 | C7: 0.57717973
A8: NotNewCellphoneUser | B8: 26908 | C8: 0.62962032
A9: NewCellphoneUser | B9: 23350 | C9: 0.67512677
A10: RVOwner | B10: 22352 | C10: 0.71868824
A11: HandsetRefurbished | B11: 20852 | C11: 0.75932639
A12: MaritalStatus | B12: 20503 | C12: 0.79928437
A13: TruckOwner | B13: 20254 | C13: 0.83875708
A14: BuysViaMailOrder | B14: 18925 | C14: 0.87563972
... A19: ChildrenInHH | B19: 6700 | C19: 1

Sheet Endirim
B4: Müştərilər | C4: Ən bahalı tarif Qiymeti | D4: Ən bahalı tarif | E4: Son alinan tarif id | F4: Son alinan tarif qiymeti | G4: Endirim | H4: Endirim olunacaq Kompaniya
B5: Cooper Rowantree | C5: 65 | D5: HasCreditCard | E5: cam17 | F5: 29 | G5: Endirim | H5: HasCreditCard
B6: Arlan Boow | C6: 62 | D6: HandsetWebCapable | E6: cam16 | F6: 16 | G6: Endirim | H6: HandsetWebCapable
B7: Sascha Pittock | C7: 62 | D7: HandsetWebCapable | E7: cam14 | F7: 28 | G7: Endirim | H7: HandsetWebCapable
B8: Feliks Datte | C8: 29 | D8: MaritalStatus | E8: cam17 | F8: 29
B9: Goddart Drage | C9: 27 | D9: RespondsToMailOffers | E9: cam06 | F9: 13 | G9: Endirim | H9: RespondsToMailOffers
B10: Jenine Swateridge | C10: 62 | D10: HandsetWebCapable | E10: cam11 | F10: 62
B11: Bonny Crowd | C11: 27 | D11: RespondsToMailOffers | E11: cam12 | F11: 65
B12: Kylen Stanluck | C12: 65 | D12: HasCreditCard | E12: cam16 | F12: 16 | G12: Endirim | H12: HasCreditCard
B13: Donnajean Belz | C13: 14 | D13: OwnsMotorcycle | E13: cam15 | F13: 14
B14: Thomasin Bulley | C14: 75 | D14: OptOutMailings | E14: cam17 | F14: 29 | G14: Endirim | H14: OptOutMailings
B15: Evvie MacTrusty | C15: 65 | D15: HasCreditCard | E15: cam06 | F15: 13 | G15: Endirim | H15: HasCreditCard
B16: Dinny Victory | C16: 66 | D16: NonUSTravel | E16: cam14 | F16: 28 | G16: Endirim | H16: NonUSTravel
B17: Bobbe Prandini | C17: 65 | D17: HasCreditCard | E17: cam17 | F17: 29 | G17: Endirim | H17: HasCreditCard
B18: Ginger Pinnere | C18: 26 | D18: HandsetRefurbished | E18: cam05 | F18: 22 | G18: Endirim | H18: HandsetRefurbished
B19: Katerina Maccrae | C19: 27 | D19: RespondsToMailOffers | E19: cam08 | F19: 27
B20: Enid Zanioletti | C20: 75 | D20: OptOutMailings | E20: cam08 | F20: 27 | G20: Endirim | H20: OptOutMailings
B21: Rudy Le feuvre | C21: 62 | D21: HandsetWebCapable | E21: cam16 | F21: 16 | G21: Endirim | H21: HandsetWebCapable
B22: Jemie Piche | C22: 62 | D22: HandsetWebCapable | E22: cam13 | F22: 25 | G22: Endirim | H22: HandsetWebCapable
B23: Hermia Yatman | C23: 22 | D23: RVOwner | E23: cam17 | F23: 29
B24: Dilan Nelane | C24: 26 | D24: HandsetRefurbished | E24: cam17 | F24: 29
B25: Kyla Dudin | C25: 62 | D25: HandsetWebCapable | E25: cam14 | F25: 28 | G25: Endirim | H25: HandsetWebCapable
B26: Ashby Winsom | C26: 29 | D26: MaritalStatus | E26: cam13 | F26: 25 | G26: Endirim | H26: MaritalStatus
B27: Derward Probetts | C27: 62 | D27: HandsetWebCapable | E27: cam03 | F27: 62
B28: Ursuline Fitzjohn | C28: 65 | D28: HasCreditCard | E28: cam03 | F28: 62 | G28: Endirim | H28: HasCreditCard
B29: Betteann Carress | C29: 27 | D29: RespondsToMailOffers | E29: cam02 | F29: 26 | G29: Endirim | H29: RespondsToMailOffers
B30: Godfrey Jaime | C30: 27 | D30: RespondsToMailOffers | E30: cam17 | F30: 29
B31: Melli Matteris | C31: 75 | D31: OptOutMailings | E31: cam16 | F31: 16 | G31: Endirim | H31: OptOutMailings
B32: Beale Hazeldine | C32: 75 | D32: OptOutMailings | E32: cam17 | F32: 29 | G32: Endirim | H32: OptOutMailings
B33: Lorita Eaglen | C33: 66 | D33: NonUSTravel | E33: cam17 | F33: 29 | G33: Endirim | H33: NonUSTravel
B34: Joeann Strewther | C34: 26 | D34: HandsetRefurbished | E34: cam17 | F34: 29
B35: Ganny Eric | C35: 29 | D35: MaritalStatus | E35: cam17 | F35: 29
B36: Lorant Le Surf | C36: 62 | D36: HandsetWebCapable | E36: cam17 | F36: 29 | G36: Endirim | H36: HandsetWebCapable
B37: Petrina Moscone | C37: 66 | D37: NonUSTravel | E37: cam17 | F37: 29 | G37: Endirim | H37: NonUSTravel
B38: Roman Cunnah | C38: 62 | D38: HandsetWebCapable | E38: cam08 | F38: 27 | G38: Endirim | H38: HandsetWebCapable
B39: Irvine Mutton | C39: 66 | D39: NonUSTravel | E39: cam05 | F39: 22 | G39: Endirim | H39: NonUSTravel
B40: Tabbie Tolossi | C40: 66 | D40: NonUSTravel | E40: cam12 | F40: 65 | G40: Endirim | H40: NonUSTravel
B41: Rutherford Messenger | C41: 62 | D41: HandsetWebCapable | E41: cam17 | F41: 29 | G41: Endirim | H41: HandsetWebCapable
B42: Pascale Rollinson | C42: 75 | D42: OptOutMailings | E42: cam11 | F42: 62 | G42: Endirim | H42: OptOutMailings
B43: Brice Craker | C43: 75 | D43: OptOutMailings | E43: cam05 | F43: 22 | G43: Endirim | H43: OptOutMailings
...

Sheet Kompaniyalar
A1: id | B1: campaign_name | C1: activate_date | D1: campaign_price
A2: cam01 | B2: ChildrenInHH | C2: 44699 | D2: 10
A3: cam02 | B3: HandsetRefurbished | C3: 43041 | D3: 26
A4: cam03 | B4: HandsetWebCapable | C4: 43779 | D4: 62
A5: cam04 | B5: TruckOwner | C5: 43502 | D5: 26
A6: cam05 | B6: RVOwner | C6: 42352 | D6: 22
A7: cam06 | B7: Homeownership | C7: 44156 | D7: 13
A8: cam07 | B8: BuysViaMailOrder | C8: 42141 | D8: 25
A9: cam08 | B9: RespondsToMailOffers | C9: 44736 | D9: 27
A10: cam09 | B10: OptOutMailings | C10: 43695 | D10: 75
A11: cam10 | B11: NonUSTravel | C11: 42596 | D11: 66
A12: cam11 | B12: OwnsComputer | C12: 42623 | D12: 62
A13: cam12 | B13: HasCreditCard | C13: 44532 | D13: 65
... A18: cam17 | B18: MaritalStatus | C18: 44744 | D18: 29

Sheet Müştərilər
A1: id | B1: full_name | C1: email | D1: gsm_number | E1: customer_age | F1: customer_gender
A2: C0001 | B2: Cooper Rowantree | C2: crowantree0@unc.edu | D2: 971-205-0249 | E2: 35 | F2: Male
A3: C0002 | B3: Arlan Boow | C3: aboow1@upenn.edu | D3: 587-456-6601 | E3: 58 | F3: Male
A4: C0003 | B4: Sascha Pittock | C4: spittock2@bluehost.com | D4: 197-660-7732 | E4: 29 | F4: Male
A5: C0004 | B5: Feliks Datte | C5: fdatte3@hp.com | D5: 402-819-2990 | E5: 61 | F5: Male
A6: C0005 | B6: Goddart Drage | C6: gdrage4@samsung.com | D6: 113-208-8207 | E6: 63 | F6: Female
A7: C0006 | B7: Jenine Swateridge | C7: jswateridge5@bravesites.com | D7: 980-499-2623 | E7: 82 | F7: Female
A8: C0007 | B8: Bonny Crowd | C8: bcrowd6@auda.org.au | D8: 500-318-4540 | E8: 36 | F8: Female
A9: C0008 | B9: Kylen Stanluck | C9: kstanluck7@yellowbook.com | D9: 132-349-0937 | E9: 47 | F9: Female
A10: C0009 | B10: Donnajean Belz | C10: dbelz8@storify.com | D10: 209-266-8420 | E10: 68 | F10: Male
A11: C0010 | B11: Thomasin Bulley | C11: tbulley9@cisco.com | D11: 392-290-2626 | E11: 50 | F11: Male
A12: C0011 | B12: Evvie MacTrusty | C12: emactrustya@ustream.tv | D12: 417-754-3818 | E12: 21 | F12: Male
A13: C0012 | B13: Dinny Victory | C13: dvictoryb@msu.edu | D13: 662-638-5210 | E13: 33 | F13: Female
... A978: C0977 | B978: Bili Pairpoint | C978: bpairpointr4@altervista.org | D978: 268-447-6625 | E978: 47 | F978: Male

Sheet satış
A1: id_customer | B1: id_campaign | C1: join_date | D1: buy_date | E1: Tarif Qiyməti
A2: C0001 | B2: cam12 | C2: 44813 | D2: 44813 | E2: =VLOOKUP(satış[[#This Row],[id_campaign]],kompaniyalar[#All],4,FALSE) -> 65
A3: C0001 | B3: cam12 | C3: 44813 | D3: 44907 | E3: =VLOOKUP(satış[[#This Row],[id_campaign]],kompaniyalar[#All],4,FALSE) -> 65
A4: C0001 | B4: cam12 | C4: 44813 | D4: 44935 | E4: =VLOOKUP(satış[[#This Row],[id_campaign]],kompaniyalar[#All],4,FALSE) -> 65
A5: C0001 | B5: cam12 | C5: 44813 | D5: 44974 | E5: =VLOOKUP(satış[[#This Row],[id_campaign]],kompaniyalar[#All],4,FALSE) -> 65
A6: C0001 | B6: cam12 | C6: 44813 | D6: 45006 | E6: =VLOOKUP(satış[[#This Row],[id_campaign]],kompaniyalar[#All],4,FALSE) -> 65
A7: C0001 | B7: cam12 | C7: 44813 | D7: 45040 | E7: =VLOOKUP(satış[[#This Row],[id_campaign]],kompaniyalar[#All],4,FALSE) -> 65
A8: C0001 | B8: cam12 | C8: 44813 | D8: 45065 | E8: =VLOOKUP(satış[[#This Row],[id_campaign]],kompaniyalar[#All],4,FALSE) -> 65
A9: C0001 | B9: cam07 | C9: 44850 | D9: 44850 | E9: =VLOOKUP(satış[[#This Row],[id_campaign]],kompaniyalar[#All],4,FALSE) -> 25
A10: C0001 | B10: cam07 | C10: 44850 | D10: 44956 | E10: =VLOOKUP(satış[[#This Row],[id_campaign]],kompaniyalar[#All],4,FALSE) -> 25
A11: C0001 | B11: cam07 | C11: 44850 | D11: 44982 | E11: =VLOOKUP(satış[[#This Row],[id_campaign]],kompaniyalar[#All],4,FALSE) -> 25
A12: C0001 | B12: cam07 | C12: 44850 | D12: 45008 | E12: =VLOOKUP(satış[[#This Row],[id_campaign]],kompaniyalar[#All],4,FALSE) -> 25
A13: C0001 | B13: cam07 | C13: 44850 | D13: 45045 | E13: =VLOOKUP(satış[[#This Row],[id_campaign]],kompaniyalar[#All],4,FALSE) -> 25
... A15018: C0977 | B15018: cam05 | C15018: 44937 | D15018: 45068 | E15018: =VLOOKUP(satış[[#This Row],[id_campaign]],kompaniyalar[#All],4,FALSE) -> 22

Sheet Data
B2: Müştərilər | C2: Müştəri İD | D2: Ən bahalı tarif Qiymeti | E2: Ən bahalı tarif | F2: Son alis tarixi | G2: Son alinan tarif id | H2: Son alinan tarif qiymeti | I2: Endirim | J2: Endirim olunacaq Kompaniya
B3: Cooper Rowantree | C3: C0001 | D3: =_xlfn.MAXIFS(satış[Tarif Qiyməti],satış[id_customer],Data!C3) -> 65 | E3: {=_xlfn.XLOOKUP(D3,kompaniyalar[[#All],[campaign_price]],kompaniyalar[[#All],[campaign_name]],,0)} -> HasCreditCard | F3: =_xlfn.MAXIFS(satış[buy_date],satış[id_customer],Data!C3) -> 45082 | G3: =_xlfn.XLOOKUP(F3,satış[buy_date],satış[id_campaign],,0) -> cam17 | H3: =VLOOKUP(G3,kompaniyalar[],4,FALSE) -> 29 | I3: =IF(H3<D3,"Endirim","") -> Endirim | J3: =IF(I3="Endirim",E3,"") -> HasCreditCard
B4: Arlan Boow | C4: C0002 | D4: =_xlfn.MAXIFS(satış[Tarif Qiyməti],satış[id_customer],Data!C4) -> 62 | E4: {=_xlfn.XLOOKUP(D4,kompaniyalar[[#All],[campaign_price]],kompaniyalar[[#All],[campaign_name]],,0)} -> HandsetWebCapable | F4: =_xlfn.MAXIFS(satış[buy_date],satış[id_customer],Data!C4) -> 45069 | G4: =_xlfn.XLOOKUP(F4,satış[buy_date],satış[id_campaign],,0) -> cam16 | H4: =VLOOKUP(G4,kompaniyalar[],4,FALSE) -> 16 | I4: =IF(H4<D4,"Endirim","") -> Endirim | J4: =IF(I4="Endirim",E4,"") -> HandsetWebCapable
B5: Sascha Pittock | C5: C0003 | D5: =_xlfn.MAXIFS(satış[Tarif Qiyməti],satış[id_customer],Data!C5) -> 62 | E5: {=_xlfn.XLOOKUP(D5,kompaniyalar[[#All],[campaign_price]],kompaniyalar[[#All],[campaign_name]],,0)} -> HandsetWebCapable | F5: =_xlfn.MAXIFS(satış[buy_date],satış[id_customer],Data!C5) -> 45086 | G5: =_xlfn.XLOOKUP(F5,satış[buy_date],satış[id_campaign],,0) -> cam14 | H5: =VLOOKUP(G5,kompaniyalar[],4,FALSE) -> 28 | I5: =IF(H5<D5,"Endirim","") -> Endirim | J5: =IF(I5="Endirim",E5,"") -> HandsetWebCapable
B6: Feliks Datte | C6: C0004 | D6: =_xlfn.MAXIFS(satış[Tarif Qiyməti],satış[id_customer],Data!C6) -> 29 | E6: {=_xlfn.XLOOKUP(D6,kompaniyalar[[#All],[campaign_price]],kompaniyalar[[#All],[campaign_name]],,0)} -> MaritalStatus | F6: =_xlfn.MAXIFS(satış[buy_date],satış[id_customer],Data!C6) -> 45084 | G6: =_xlfn.XLOOKUP(F6,satış[buy_date],satış[id_campaign],,0) -> cam17 | H6: =VLOOKUP(G6,kompaniyalar[],4,FALSE) -> 29 | I6: =IF(H6<D6,"Endirim","") | J6: =IF(I6="Endirim",E6,"")
B7: Goddart Drage | C7: C0005 | D7: =_xlfn.MAXIFS(satış[Tarif Qiyməti],satış[id_customer],Data!C7) -> 27 | E7: {=_xlfn.XLOOKUP(D7,kompaniyalar[[#All],[campaign_price]],kompaniyalar[[#All],[campaign_name]],,0)} -> RespondsToMailOffers | F7: =_xlfn.MAXIFS(satış[buy_date],satış[id_customer],Data!C7) -> 45078 | G7: =_xlfn.XLOOKUP(F7,satış[buy_date],satış[id_campaign],,0) -> cam06 | H7: =VLOOKUP(G7,kompaniyalar[],4,FALSE) -> 13 | I7: =IF(H7<D7,"Endirim","") -> Endirim | J7: =IF(I7="Endirim",E7,"") -> RespondsToMailOffers
B8: Jenine Swateridge | C8: C0006 | D8: =_xlfn.MAXIFS(satış[Tarif Qiyməti],satış[id_customer],Data!C8) -> 62 | E8: {=_xlfn.XLOOKUP(D8,kompaniyalar[[#All],[campaign_price]],kompaniyalar[[#All],[campaign_name]],,0)} -> HandsetWebCapable | F8: =_xlfn.MAXIFS(satış[buy_date],satış[id_customer],Data!C8) -> 45080 | G8: =_xlfn.XLOOKUP(F8,satış[buy_date],satış[id_campaign],,0) -> cam11 | H8: =VLOOKUP(G8,kompaniyalar[],4,FALSE) -> 62 | I8: =IF(H8<D8,"Endirim","") | J8: =IF(I8="Endirim",E8,"")
B9: Bonny Crowd | C9: C0007 | D9: =_xlfn.MAXIFS(satış[Tarif Qiyməti],satış[id_customer],Data!C9) -> 27 | E9: {=_xlfn.XLOOKUP(D9,kompaniyalar[[#All],[campaign_price]],kompaniyalar[[#All],[campaign_name]],,0)} -> RespondsToMailOffers | F9: =_xlfn.MAXIFS(satış[buy_date],satış[id_customer],Data!C9) -> 45065 | G9: =_xlfn.XLOOKUP(F9,satış[buy_date],satış[id_campaign],,0) -> cam12 | H9: =VLOOKUP(G9,kompaniyalar[],4,FALSE) -> 65 | I9: =IF(H9<D9,"Endirim","") | J9: =IF(I9="Endirim",E9,"")
B10: Kylen Stanluck | C10: C0008 | D10: =_xlfn.MAXIFS(satış[Tarif Qiyməti],satış[id_customer],Data!C10) -> 65 | E10: {=_xlfn.XLOOKUP(D10,kompaniyalar[[#All],[campaign_price]],kompaniyalar[[#All],[campaign_name]],,0)} -> HasCreditCard | F10: =_xlfn.MAXIFS(satış[buy_date],satış[id_customer],Data!C10) -> 45058 | G10: =_xlfn.XLOOKUP(F10,satış[buy_date],satış[id_campaign],,0) -> cam16 | H10: =VLOOKUP(G10,kompaniyalar[],4,FALSE) -> 16 | I10: =IF(H10<D10,"Endirim","") -> Endirim | J10: =IF(I10="Endirim",E10,"") -> HasCreditCard
B11: Donnajean Belz | C11: C0009 | D11: =_xlfn.MAXIFS(satış[Tarif Qiyməti],satış[id_customer],Data!C11) -> 14 | E11: {=_xlfn.XLOOKUP(D11,kompaniyalar[[#All],[campaign_price]],kompaniyalar[[#All],[campaign_name]],,0)} -> OwnsMotorcycle | F11: =_xlfn.MAXIFS(satış[buy_date],satış[id_customer],Data!C11) -> 45081 | G11: =_xlfn.XLOOKUP(F11,satış[buy_date],satış[id_campaign],,0) -> cam15 | H11: =VLOOKUP(G11,kompaniyalar[],4,FALSE) -> 14 | I11: =IF(H11<D11,"Endirim","") | J11: =IF(I11="Endirim",E11,"")
B12: Thomasin Bulley | C12: C0010 | D12: =_xlfn.MAXIFS(satış[Tarif Qiyməti],satış[id_customer],Data!C12) -> 75 | E12: {=_xlfn.XLOOKUP(D12,kompaniyalar[[#All],[campaign_price]],kompaniyalar[[#All],[campaign_name]],,0)} -> OptOutMailings | F12: =_xlfn.MAXIFS(satış[buy_date],satış[id_customer],Data!C12) -> 45072 | G12: =_xlfn.XLOOKUP(F12,satış[buy_date],satış[id_campaign],,0) -> cam17 | H12: =VLOOKUP(G12,kompaniyalar[],4,FALSE) -> 29 | I12: =IF(H12<D12,"Endirim","") -> Endirim | J12: =IF(I12="Endirim",E12,"") -> OptOutMailings
B13: Evvie MacTrusty | C13: C0011 | D13: =_xlfn.MAXIFS(satış[Tarif Qiyməti],satış[id_customer],Data!C13) -> 65 | E13: {=_xlfn.XLOOKUP(D13,kompaniyalar[[#All],[campaign_price]],kompaniyalar[[#All],[campaign_name]],,0)} -> HasCreditCard | F13: =_xlfn.MAXIFS(satış[buy_date],satış[id_customer],Data!C13) -> 45078 | G13: =_xlfn.XLOOKUP(F13,satış[buy_date],satış[id_campaign],,0) -> cam06 | H13: =VLOOKUP(G13,kompaniyalar[],4,FALSE) -> 13 | I13: =IF(H13<D13,"Endirim","") -> Endirim | J13: =IF(I13="Endirim",E13,"") -> HasCreditCard
B14: Dinny Victory | C14: C0012 | D14: =_xlfn.MAXIFS(satış[Tarif Qiyməti],satış[id_customer],Data!C14) -> 66 | E14: {=_xlfn.XLOOKUP(D14,kompaniyalar[[#All],[campaign_price]],kompaniyalar[[#All],[campaign_name]],,0)} -> NonUSTravel | F14: =_xlfn.MAXIFS(satış[buy_date],satış[id_customer],Data!C14) -> 45086 | G14: =_xlfn.XLOOKUP(F14,satış[buy_date],satış[id_campaign],,0) -> cam14 | H14: =VLOOKUP(G14,kompaniyalar[],4,FALSE) -> 28 | I14: =IF(H14<D14,"Endirim","") -> Endirim | J14: =IF(I14="Endirim",E14,"") -> NonUSTravel
... B979: Bili Pairpoint | C979: C0977 | D979: =_xlfn.MAXIFS(satış[Tarif Qiyməti],satış[id_customer],Data!C979) -> 75 | E979: {=_xlfn.XLOOKUP(D979,kompaniyalar[[#All],[campaign_price]],kompaniyalar[[#All],[campaign_name]],,0)} -> OptOutMailings | F979: =_xlfn.MAXIFS(satış[buy_date],satış[id_customer],Data!C979) -> 45068 | G979: =_xlfn.XLOOKUP(F979,satış[buy_date],satış[id_campaign],,0) -> cam08 | H979: =VLOOKUP(G979,kompaniyalar[],4,FALSE) -> 27 | I979: =IF(H979<D979,"Endirim","") -> Endirim | J979: =IF(I979="Endirim",E979,"") -> OptOutMailings
